<?xml version="1.0" encoding="utf-8"?>
<!-- This URDF was automatically created by SolidWorks to URDF Exporter! Originally created by Stephen Brawner (brawner@gmail.com) 
     Commit Version: 1.6.0-4-g7f85cfe  Build Version: 1.6.7995.38578
     For more information, please see http://wiki.ros.org/sw_urdf_exporter -->
<robot
  name="Rover_5_URDF_MESHES.SLDASM">
  <link
    name="base_link">
    <inertial>
      <origin
        xyz="0.00042066 0.025289 1.275E-07"
        rpy="0 0 0" />
      <mass
        value="0.23083" />
      <inertia
        ixx="0.00023965"
        ixy="1.2352E-06"
        ixz="2.1236E-09"
        iyy="0.00082819"
        iyz="-2.1159E-10"
        izz="0.0006395" />
    </inertial>
    <visual>
      <origin
        xyz="0 0 0"
        rpy="0 0 0" />
      <geometry>
        <mesh
          filename="package://Rover_5_URDF_MESHES.SLDASM/meshes/base_link.STL" />
      </geometry>
      <material
        name="">
        <color
          rgba="0.75294 0.75294 0.75294 1" />
      </material>
    </visual>
    <collision>
      <origin
        xyz="0 0 0"
        rpy="0 0 0" />
      <geometry>
        <mesh
          filename="package://Rover_5_URDF_MESHES.SLDASM/meshes/base_link.STL" />
      </geometry>
    </collision>
  </link>
  <link
    name="front_right_wheel_connector">
    <inertial>
      <origin
        xyz="-0.0414 -0.0024406 0.00050337"
        rpy="0 0 0" />
      <mass
        value="0.1526" />
      <inertia
        ixx="4.7307E-05"
        ixy="-3.6445E-07"
        ixz="3.0373E-05"
        iyy="0.00020097"
        iyz="1.8462E-07"
        izz="0.00018236" />
    </inertial>
    <visual>
      <origin
        xyz="0 0 0"
        rpy="0 0 0" />
      <geometry>
        <mesh
          filename="package://Rover_5_URDF_MESHES.SLDASM/meshes/front_right_wheel_connector.STL" />
      </geometry>
      <material
        name="">
        <color
          rgba="1 1 1 1" />
      </material>
    </visual>
    <collision>
      <origin
        xyz="0 0 0"
        rpy="0 0 0" />
      <geometry>
        <mesh
          filename="package://Rover_5_URDF_MESHES.SLDASM/meshes/front_right_wheel_connector.STL" />
      </geometry>
    </collision>
  </link>
  <joint
    name="base_link_to_right_wheel_connector"
    type="fixed">
    <origin
      xyz="-0.038432 0.0665 0.0015968"
      rpy="-1.5708 -0.2402 0" />
    <parent
      link="base_link" />
    <child
      link="front_right_wheel_connector" />
    <axis
      xyz="0 0 0" />
  </joint>
  <link
    name="front_right_wheel">
    <inertial>
      <origin
        xyz="3.6637E-11 2.8501E-11 -0.018857"
        rpy="0 0 0" />
      <mass
        value="0.016981" />
      <inertia
        ixx="6.6928E-06"
        ixy="1.5044E-14"
        ixz="2.1669E-14"
        iyy="6.6928E-06"
        iyz="-2.7239E-14"
        izz="9.0681E-06" />
    </inertial>
    <visual>
      <origin
        xyz="0 0 0"
        rpy="0 0 0" />
      <geometry>
        <mesh
          filename="package://Rover_5_URDF_MESHES.SLDASM/meshes/front_right_wheel.STL" />
      </geometry>
      <material
        name="">
        <color
          rgba="1 1 1 1" />
      </material>
    </visual>
    <collision>
      <origin
        xyz="0 0 0"
        rpy="0 0 0" />
      <geometry>
        <mesh
          filename="package://Rover_5_URDF_MESHES.SLDASM/meshes/front_right_wheel.STL" />
      </geometry>
    </collision>
  </link>
  <joint
    name="front_right_wheel_connector_to_front_right_wheel"
    type="continuous">
    <origin
      xyz="-0.08 0 0.0605"
      rpy="0 0 2.5298" />
    <parent
      link="front_right_wheel_connector" />
    <child
      link="front_right_wheel" />
    <axis
      xyz="0 0 0" />
  </joint>
  <link
    name="front_left_wheel_connector">
    <inertial>
      <origin
        xyz="-0.0414 -0.0024406 0.00050337"
        rpy="0 0 0" />
      <mass
        value="0.1526" />
      <inertia
        ixx="4.7307E-05"
        ixy="-3.6445E-07"
        ixz="3.0373E-05"
        iyy="0.00020097"
        iyz="1.8462E-07"
        izz="0.00018236" />
    </inertial>
    <visual>
      <origin
        xyz="0 0 0"
        rpy="0 0 0" />
      <geometry>
        <mesh
          filename="package://Rover_5_URDF_MESHES.SLDASM/meshes/front_left_wheel_connector.STL" />
      </geometry>
      <material
        name="">
        <color
          rgba="1 1 1 1" />
      </material>
    </visual>
    <collision>
      <origin
        xyz="0 0 0"
        rpy="0 0 0" />
      <geometry>
        <mesh
          filename="package://Rover_5_URDF_MESHES.SLDASM/meshes/front_left_wheel_connector.STL" />
      </geometry>
    </collision>
  </link>
  <joint
    name="base_link_to_front_left_wheel_connector"
    type="fixed">
    <origin
      xyz="-0.04 -0.0665 0.008"
      rpy="1.5708 -0.2402 0" />
    <parent
      link="base_link" />
    <child
      link="front_left_wheel_connector" />
    <axis
      xyz="0 0 0" />
  </joint>
  <link
    name="front_left_wheel">
    <inertial>
      <origin
        xyz="3.6637E-11 2.8501E-11 -0.018857"
        rpy="0 0 0" />
      <mass
        value="0.016981" />
      <inertia
        ixx="6.6928E-06"
        ixy="1.5044E-14"
        ixz="2.1669E-14"
        iyy="6.6928E-06"
        iyz="-2.7239E-14"
        izz="9.0681E-06" />
    </inertial>
    <visual>
      <origin
        xyz="0 0 0"
        rpy="0 0 0" />
      <geometry>
        <mesh
          filename="package://Rover_5_URDF_MESHES.SLDASM/meshes/front_left_wheel.STL" />
      </geometry>
      <material
        name="">
        <color
          rgba="1 1 1 1" />
      </material>
    </visual>
    <collision>
      <origin
        xyz="0 0 0"
        rpy="0 0 0" />
      <geometry>
        <mesh
          filename="package://Rover_5_URDF_MESHES.SLDASM/meshes/front_left_wheel.STL" />
      </geometry>
    </collision>
  </link>
  <joint
    name="front_left_wheel_connector_to_front_left_wheel"
    type="continuous">
    <origin
      xyz="-0.08 0 0.0605"
      rpy="0 0 3.0303" />
    <parent
      link="front_left_wheel_connector" />
    <child
      link="front_left_wheel" />
    <axis
      xyz="0 0 0" />
  </joint>
  <link
    name="back_right_wheel_connector">
    <inertial>
      <origin
        xyz="-0.0414 -0.0024406 -0.00050337"
        rpy="0 0 0" />
      <mass
        value="0.1526" />
      <inertia
        ixx="4.7307E-05"
        ixy="-3.6445E-07"
        ixz="-3.0373E-05"
        iyy="0.00020097"
        iyz="-1.8462E-07"
        izz="0.00018236" />
    </inertial>
    <visual>
      <origin
        xyz="0 0 0"
        rpy="0 0 0" />
      <geometry>
        <mesh
          filename="package://Rover_5_URDF_MESHES.SLDASM/meshes/back_right_wheel_connector.STL" />
      </geometry>
      <material
        name="">
        <color
          rgba="1 1 1 1" />
      </material>
    </visual>
    <collision>
      <origin
        xyz="0 0 0"
        rpy="0 0 0" />
      <geometry>
        <mesh
          filename="package://Rover_5_URDF_MESHES.SLDASM/meshes/back_right_wheel_connector.STL" />
      </geometry>
    </collision>
  </link>
  <joint
    name="base_link_to_back_right_wheel_connector"
    type="fixed">
    <origin
      xyz="0.038096 0.0665 0.0016884"
      rpy="-1.5708 -0.29297 3.1416" />
    <parent
      link="base_link" />
    <child
      link="back_right_wheel_connector" />
    <axis
      xyz="0 0 0" />
  </joint>
  <link
    name="back_right_wheel">
    <inertial>
      <origin
        xyz="3.6637E-11 2.8501E-11 -0.018857"
        rpy="0 0 0" />
      <mass
        value="0.016981" />
      <inertia
        ixx="6.6928E-06"
        ixy="1.5044E-14"
        ixz="2.1669E-14"
        iyy="6.6928E-06"
        iyz="-2.7239E-14"
        izz="9.0681E-06" />
    </inertial>
    <visual>
      <origin
        xyz="0 0 0"
        rpy="0 0 0" />
      <geometry>
        <mesh
          filename="package://Rover_5_URDF_MESHES.SLDASM/meshes/back_right_wheel.STL" />
      </geometry>
      <material
        name="">
        <color
          rgba="1 1 1 1" />
      </material>
    </visual>
    <collision>
      <origin
        xyz="0 0 0"
        rpy="0 0 0" />
      <geometry>
        <mesh
          filename="package://Rover_5_URDF_MESHES.SLDASM/meshes/back_right_wheel.STL" />
      </geometry>
    </collision>
  </link>
  <joint
    name="back_right_wheel_connector_to_back_right_wheel"
    type="continuous">
    <origin
      xyz="-0.08 0 -0.0605"
      rpy="3.1416 0 1.845" />
    <parent
      link="back_right_wheel_connector" />
    <child
      link="back_right_wheel" />
    <axis
      xyz="0 0 0" />
  </joint>
  <link
    name="back_left_wheel_connector">
    <inertial>
      <origin
        xyz="-0.0414 -0.0024406 -0.00050337"
        rpy="0 0 0" />
      <mass
        value="0.1526" />
      <inertia
        ixx="4.7307E-05"
        ixy="-3.6445E-07"
        ixz="-3.0373E-05"
        iyy="0.00020097"
        iyz="-1.8462E-07"
        izz="0.00018236" />
    </inertial>
    <visual>
      <origin
        xyz="0 0 0"
        rpy="0 0 0" />
      <geometry>
        <mesh
          filename="package://Rover_5_URDF_MESHES.SLDASM/meshes/back_left_wheel_connector.STL" />
      </geometry>
      <material
        name="">
        <color
          rgba="1 1 1 1" />
      </material>
    </visual>
    <collision>
      <origin
        xyz="0 0 0"
        rpy="0 0 0" />
      <geometry>
        <mesh
          filename="package://Rover_5_URDF_MESHES.SLDASM/meshes/back_left_wheel_connector.STL" />
      </geometry>
    </collision>
  </link>
  <joint
    name="base_link_to_back_left_wheel_connector"
    type="fixed">
    <origin
      xyz="0.04 -0.0665 0.008"
      rpy="1.5707963267949 -0.292974408119726 3.14159265358979" />
    <parent
      link="base_link" />
    <child
      link="back_left_wheel_connector" />
    <axis
      xyz="0 0 0" />
  </joint>
  <link
    name="back_left_wheel">
    <inertial>
      <origin
        xyz="3.6637E-11 2.8501E-11 -0.018857"
        rpy="0 0 0" />
      <mass
        value="0.016981" />
      <inertia
        ixx="6.6928E-06"
        ixy="1.5044E-14"
        ixz="2.1669E-14"
        iyy="6.6928E-06"
        iyz="-2.7239E-14"
        izz="9.0681E-06" />
    </inertial>
    <visual>
      <origin
        xyz="0 0 0"
        rpy="0 0 0" />
      <geometry>
        <mesh
          filename="package://Rover_5_URDF_MESHES.SLDASM/meshes/back_left_wheel.STL" />
      </geometry>
      <material
        name="">
        <color
          rgba="1 1 1 1" />
      </material>
    </visual>
    <collision>
      <origin
        xyz="0 0 0"
        rpy="0 0 0" />
      <geometry>
        <mesh
          filename="package://Rover_5_URDF_MESHES.SLDASM/meshes/back_left_wheel.STL" />
      </geometry>
    </collision>
  </link>
  <joint
    name="back_left_wheel_connector_to_back_left_wheel"
    type="continuous">
    <origin
      xyz="-0.08 0 -0.0605"
      rpy="3.1416 0 1.7173" />
    <parent
      link="back_left_wheel_connector" />
    <child
      link="back_left_wheel" />
    <axis
      xyz="0 0 0" />
  </joint>
</robot>